<?xml version="1.0"?>

<robot name="opera">

    <link name="base_link">
	<inertial>
            <origin xyz="0 0 0" rpy="0 0 0"/>
            <mass value="0.01" />
            <inertia ixx="7.58333333333e-06" ixy="0.0" ixz="0.0" iyy="7.58333333333e-06" iyz="0.0" izz="1.25e-05"/>
        </inertial>

	<collision>
		<origin rpy="0 0 0" xyz="0 0 0"/>
		<geometry>
		    <mesh filename="package://opera_description/models/base.dae"/>
		</geometry>
        </collision>

        <visual>
		<origin rpy="0 0 0" xyz="0 0 0"/>
		<geometry>
		    <mesh filename="package://opera_description/models/base.dae"/>
		</geometry>
        </visual>
    </link>
  
    <link name="wheel_r1">
	<inertial>
            <origin xyz="0 0 0" rpy="0 0 0"/>
            <mass value="0.01" />
            <inertia ixx="7.58333333333e-06" ixy="0.0" ixz="0.0" iyy="7.58333333333e-06" iyz="0.0" izz="1.25e-05"/>
        </inertial>

	<collision>
            <origin rpy="0 0 0" xyz="0 0 0"/>
            <geometry>
                <mesh filename="package://opera_description/models/llanta.dae"/>
            </geometry>
        </collision>

        <visual>
            <origin rpy="0 0 0" xyz="0 0 0"/>
            <geometry>
                <mesh filename="package://opera_description/models/llanta.dae"/>
            </geometry>
        </visual>
    </link>

    <link name="wheel_r2">
	<inertial>
            <origin xyz="0 0 0" rpy="0 0 0"/>
            <mass value="0.01" />
            <inertia ixx="7.58333333333e-06" ixy="0.0" ixz="0.0" iyy="7.58333333333e-06" iyz="0.0" izz="1.25e-05"/>
        </inertial>

	<collision>
            <origin rpy="0 0 0" xyz="0 0 0"/>
            <geometry>
                <mesh filename="package://opera_description/models/llanta.dae"/>
            </geometry>
        </collision>

        <visual>
            <origin rpy="0 0 0" xyz="0 0 0"/>
            <geometry>
                <mesh filename="package://opera_description/models/llanta.dae"/>
            </geometry>
        </visual>
    </link>

    <link name="wheel_l1">
	<inertial>
            <origin xyz="0 0 0" rpy="0 0 0"/>
            <mass value="0.01" />
            <inertia ixx="7.58333333333e-06" ixy="0.0" ixz="0.0" iyy="7.58333333333e-06" iyz="0.0" izz="1.25e-05"/>
        </inertial>

	<collision>
            <origin rpy="0 0 0" xyz="0 0 0"/>
            <geometry>
                <mesh filename="package://opera_description/models/llanta.dae"/>
            </geometry>
        </collision>

        <visual>
            <origin rpy="0 0 0" xyz="0 0 0"/>
            <geometry>
                <mesh filename="package://opera_description/models/llanta.dae"/>
            </geometry>
        </visual>
    </link>

    <link name="wheel_l2">
	<inertial>
            <origin xyz="0 0 0" rpy="0 0 0"/>
            <mass value="0.01" />
            <inertia ixx="7.58333333333e-06" ixy="0.0" ixz="0.0" iyy="7.58333333333e-06" iyz="0.0" izz="1.25e-05"/>
        </inertial>

	<visual>
            <origin rpy="0 0 0" xyz="0 0 0"/>
            <geometry>
                <mesh filename="package://opera_description/models/llanta.dae"/>
            </geometry>
        </visual>

        <collision>
            <origin rpy="0 0 0" xyz="0 0 0"/>
            <geometry>
                <mesh filename="package://opera_description/models/llanta.dae"/>
            </geometry>
        </collision>
    </link>

    <joint name="motor1" type="continuous">
        <parent link="base_link"/>
        <child link="wheel_r1"/>
        <origin xyz="	0.20 0.1 0.03" rpy="0 0 0"/>
        <limit effort="0.1" velocity="0.01"/>
        <axis xyz="1 0 0"/>
    </joint>

    <joint name="motor2" type="continuous">
        <parent link="base_link"/>
        <child link="wheel_r2"/>
        <origin xyz="0.20 -0.1 0.03" rpy="0 0 0"/>
        <limit effort="0.1" velocity="0.01"/>
        <axis xyz="1 0 0"/>
    </joint>

    <joint name="motor3" type="continuous">
        <parent link="base_link"/>
        <child link="wheel_l1"/>
        <origin xyz="-0.16 0.1 0.03" rpy="0 0 0"/>
        <limit effort="0.1" velocity="0.01"/>
        <axis xyz="1 0 0"/>
    </joint>

    <joint name="motor4" type="continuous">
        <parent link="base_link"/>
        <child link="wheel_l2"/>
        <origin xyz="-0.16 -0.1 0.03" rpy="0 0 0"/>
        <limit effort="0.1" velocity="0.01"/>
        <axis xyz="1 0 0"/>
    </joint>

</robot>
